
[c:\Users\╨а╤Г╤Б╨╗╨░╨╜ ╨Ъ╤Г╨╖╨╜╨╡╤Ж╨╛╨▓\bot\src\core\check_resolver.py] — 6 issue(s):
  Line 181  [ERROR] Argument missing for parameter "description"
  Line 197  [ERROR] Argument missing for parameter "description"
  Line 201  [ERROR] Argument missing for parameter "description"
  Line 293  [ERROR] Argument missing for parameter "db"
  Line 305  [ERROR] Argument missing for parameter "db"
  Line 322  [ERROR] Argument missing for parameter "db"

[c:\Users\╨а╤Г╤Б╨╗╨░╨╜ ╨Ъ╤Г╨╖╨╜╨╡╤Ж╨╛╨▓\bot\src\core\ai_response_parser.py] — 5 issue(s):
  Line 4    [ERROR] Type "ValidationError" is not assignable to declared type "type[ValidationError]"
┬а┬а"ValidationError" is not assignable to "type[ValidationError]"
┬а┬аType "ValidationError" is not assignable to type "type[ValidationError]"
  Line 137  [ERROR] Argument of type "dict[str, str]" cannot be assigned to parameter "details" of type "List[Dict[str, Any]] | None" in function "__init__"
┬а┬аType "dict[str, str]" is not assignable to type "List[Dict[str, Any]] | None"
┬а┬а┬а┬а"dict[str, str]" is not assignable to "List[Dict[str, Any]]"
┬а┬а┬а┬а"dict[str, str]" is not assignable to "None"
  Line 154  [ERROR] Argument of type "GeneratedEntity" cannot be assigned to parameter "type_" of type "type[T@parse_obj_as]" in function "parse_obj_as"
┬а┬аType "UnionType" is not assignable to type "type[T@parse_obj_as]"
  Line 156  [ERROR] "object" is not a valid exception class
  Line 172  [ERROR] "object" is not a valid exception class

[c:\Users\╨а╤Г╤Б╨╗╨░╨╜ ╨Ъ╤Г╨╖╨╜╨╡╤Ж╨╛╨▓\bot\src\core\ai_orchestrator.py] — 4 issue(s):
  Line 9    [ERROR] "create_entity" is unknown import symbol
  Line 9    [ERROR] "get_entity_by_id" is unknown import symbol
  Line 9    [ERROR] "update_entity" is unknown import symbol
  Line 66   [ERROR] Argument of type "int | None" cannot be assigned to parameter "location_id" of type "int" in function "prepare_ai_prompt"
┬а┬аType "int | None" is not assignable to type "int"
┬а┬а┬а┬а"None" is not assignable to "int"

[c:\Users\╨а╤Г╤Б╨╗╨░╨╜ ╨Ъ╤Г╨╖╨╜╨╡╤Ж╨╛╨▓\bot\src\core\crud_base_definitions.py] — 4 issue(s):
  Line 45   [ERROR] Cannot access attribute "id" for class "Base*"
┬а┬аAttribute "id" is unknown
  Line 131  [ERROR] Cannot access attribute "id" for class "Base*"
┬а┬аAttribute "id" is unknown
  Line 261  [ERROR] Cannot access attribute "guild_id" for class "Base*"
┬а┬аAttribute "guild_id" is unknown
  Line 262  [ERROR] Cannot access attribute "id" for class "Base*"
┬а┬аAttribute "id" is unknown

[c:\Users\╨а╤Г╤Б╨╗╨░╨╜ ╨Ъ╤Г╨╖╨╜╨╡╤Ж╨╛╨▓\bot\src\core\rules.py] — 4 issue(s):
  Line 8    [ERROR] "CRUDBase" is unknown import symbol
  Line 8    [ERROR] "create_entity" is unknown import symbol
  Line 8    [ERROR] "get_entity_by_id" is unknown import symbol
  Line 8    [ERROR] "update_entity" is unknown import symbol

[c:\Users\╨а╤Г╤Б╨╗╨░╨╜ ╨Ъ╤Г╨╖╨╜╨╡╤Ж╨╛╨▓\bot\src\bot\commands\master_ai_commands.py] — 3 issue(s):
  Line 14   [ERROR] "get_entity_by_id" is unknown import symbol
  Line 14   [ERROR] "update_entity" is unknown import symbol
  Line 36   [ERROR] Method "interaction_check" overrides class "Cog" in an incompatible manner
┬а┬аReturn type mismatch: base method returns type "bool", override returns type "CoroutineType[Any, Any, bool]"
┬а┬а┬а┬а"CoroutineType[Any, Any, bool]" is not assignable to "bool"

[c:\Users\╨а╤Г╤Б╨╗╨░╨╜ ╨Ъ╤Г╨╖╨╜╨╡╤Ж╨╛╨▓\bot\src\bot\commands\party_commands.py] — 3 issue(s):
  Line 38   [ERROR] "_AsyncGeneratorContextManager[AsyncSession, None]" is not iterable
┬а┬а"__aiter__" method not defined
  Line 82   [ERROR] "_AsyncGeneratorContextManager[AsyncSession, None]" is not iterable
┬а┬а"__aiter__" method not defined
  Line 131  [ERROR] "_AsyncGeneratorContextManager[AsyncSession, None]" is not iterable
┬а┬а"__aiter__" method not defined

[c:\Users\╨а╤Г╤Б╨╗╨░╨╜ ╨Ъ╤Г╨╖╨╜╨╡╤Ж╨╛╨▓\bot\src\core\ai_prompt_builder.py] — 2 issue(s):
  Line 90   [ERROR] "Never" is not iterable
  Line 192  [ERROR] Cannot access attribute "current_quest_step_id" for class "type[PlayerQuestProgress]"
┬а┬аAttribute "current_quest_step_id" is unknown

[c:\Users\╨а╤Г╤Б╨╗╨░╨╜ ╨Ъ╤Г╨╖╨╜╨╡╤Ж╨╛╨▓\bot\src\bot\commands.py] — 1 issue(s):
  Line 42   [ERROR] "_AsyncGeneratorContextManager[AsyncSession, None]" is not iterable
┬а┬а"__aiter__" method not defined

[c:\Users\╨а╤Г╤Б╨╗╨░╨╜ ╨Ъ╤Г╨╖╨╜╨╡╤Ж╨╛╨▓\bot\src\bot\utils.py] — 1 issue(s):
  Line 7    [ERROR] "get_entity_by_id" is unknown import symbol
